<?xml version="1.0"?>

<robot xmlns:xacro = "http://www.ros.org/wiki/xacro" name = "ABB_bot">

    <xacro:include filename = "$(find bot_description}/urdf/bot_gazebo.xacro"/>
    <xacro:include filename = "$(find bot_description}/urdf/bot_ros2_control.xacro"/>


    <xacro:property name="PI" value="3.14159"/>
    <xacro:property name="effort" value="30.0"/>
    <xacro:property name="velocity" value="10.0"/>

    <xacro:macro name="default_inertial" params="mass">
        <inertial>
            <mass value="${mass}"/>
            <inertia ixx="1.0" ixy="0.0" ixz="0.0"
                    iyy="1.0" iyz="0.0"
                    izz="1.0"/>
        </inertial>
    </xacro:macro>

    <xacro:macro name = "default_transmiccion" params= "number">
        <transmission name = "transmission_${number}">
            <plugin>transmission_interface/SimpleTransmission</plugin>
            <actuator name = "motor_${number}" role = "actuator1"/>
            <joint name = "joint_${number}" role = "joint1">
                <mechanical_reduction>1.0</mechanical_reduction>
            </joint>
        </transmission>
    </xacro:macro>
    
    
    <link name = "world"/>

    <link name = "base_link">
        <xacro:default_inertial mass="1.0"/>
        <visual>
            <origin rpy = "${PI/2} 0 0" xyz = "-1.2 1.95 0"/>
            <geometry>
                <mesh filename = "package://bot_description/meshes/Base_link.STL" scale = "0.01 0.01 0.01"/>
            </geometry>
        </visual>
        <collision>
            <origin rpy = "${PI/2} 0 0" xyz = "-1.2 1.95 0"/>
            <geometry>
                <mesh filename="package://bot_description/meshes/Base_link.STL" scale="0.01 0.01 0.01"/> 
            </geometry>            
        </collision>
    </link>

    <joint name = "virtual_joint" type = "fixed">
        <parent link = "world"/>
        <child link = "base_link"/>
        <origin rpy = "0 0 0" xyz = "0 0 0"/>
    </joint>

    <link name = "link_1">
        <xacro:default_inertial mass="1.0"/>
        <visual>
            <origin rpy = "${PI/2} 0 0" xyz = "-1.3 1.35 -2.2"/>
            <geometry>
                <mesh filename = "package://bot_description/meshes/Link_1.STL" scale = "0.01 0.01 0.01"/>
            </geometry>
        </visual>
        <collision>
            <origin rpy = "${PI/2} 0 0" xyz = "-1.3 1.35 -2.2"/>
            <geometry>
                <mesh filename="package://bot_description/meshes/Link_1.STL" scale="0.01 0.01 0.01"/> 
            </geometry>            
        </collision>
    </link>

    <joint name = "joint_1" type = "revolute">
        <parent link = "base_link"/>
        <child link = "link_1"/>
        <axis xyz="0 0 1"/>
        <origin rpy = "0 0 0" xyz = "0 0 2.2"/>
        <limit lower="-2.967" upper="2.967" effort="${effort}" velocity="${velocity}"/>
    </joint>

    <link name = "link_2">
        <xacro:default_inertial mass="1.0"/>
        <visual>
            <origin rpy = "${PI/2} 0 0" xyz = "-0.83 1.18 -3.95"/>
            <geometry>
                <mesh filename = "package://bot_description/meshes/Link_2.STL" scale = "0.01 0.01 0.01"/>
            </geometry>
        </visual>
        <collision>
            <origin rpy = "${PI/2} 0 0" xyz = "-0.83 1.18 -3.95"/>
            <geometry>
                <mesh filename="package://bot_description/meshes/Link_2.STL" scale="0.01 0.01 0.01"/> 
            </geometry>            
        </collision>
    </link>

    <joint name = "joint_2" type = "revolute">
        <parent link = "link_1"/>
        <child link = "link_2"/>
        <axis xyz="0 1 0"/>
        <origin rpy = "0 0 0" xyz = "0 0 1.75"/>
        <limit lower="-${PI/2}" upper="2.356" effort="${effort}" velocity="${velocity}"/>
    </joint>

    <link name = "link_3">
        <xacro:default_inertial mass="1.0"/>
        <visual>
            <origin rpy = "${PI/2} 0 0" xyz = "-0.8 0.75 -8.5"/>
            <geometry>
                <mesh filename = "package://bot_description/meshes/Link_3.STL" scale = "0.01 0.01 0.01"/>
            </geometry>
        </visual>
        <collision>
            <origin rpy = "${PI/2} 0 0" xyz = "-0.8 0.75 -8.5"/>
            <geometry>
                <mesh filename="package://bot_description/meshes/Link_3.STL" scale="0.01 0.01 0.01"/> 
            </geometry>            
        </collision>
    </link>

    <joint name = "joint_3" type = "revolute">
        <parent link = "link_2"/>
        <child link = "link_3"/>
        <axis xyz="0 1 0"/>
        <origin rpy = "0 0 0" xyz = "0 0 4.55"/>
        <limit lower="-3.490" upper="1.221" effort="${effort}" velocity="${velocity}"/>
    </joint>

    <link name = "link_4">
        <xacro:default_inertial mass="1.0"/>
        <visual>
            <origin rpy = "-${PI/2} 0 0" xyz = "-2.65 -0.65 0.97"/>
            <geometry>
                <mesh filename = "package://bot_description/meshes/Link_4.STL" scale = "0.01 0.01 0.01"/>
            </geometry>
        </visual>
        <collision>
            <origin rpy = "-${PI/2} 0 0" xyz = "-2.65 -0.65 0.97"/>
            <geometry>
                <mesh filename="package://bot_description/meshes/Link_4.STL" scale="0.01 0.01 0.01"/> 
            </geometry>            
        </collision>
    </link>

    <joint name = "joint_4" type = "revolute">
        <parent link = "link_3"/>
        <child link = "link_4"/>
        <axis xyz="1 0 0"/>
        <origin rpy = "0 0 0" xyz = "2.9 0 0.35"/>
        <limit lower="-4.712" upper="4.712" effort="${effort}" velocity="${velocity}"/>
    </joint>

    <link name = "link_5">
        <xacro:default_inertial mass="1.0"/>
        <visual>
            <origin rpy = "${PI/2} -${PI/2} 0" xyz = "1 0.47 -0.575"/>
            <geometry>
                <mesh filename = "package://bot_description/meshes/Link_5.STL" scale = "0.01 0.01 0.01"/>
            </geometry>
        </visual>
        <collision>
            <origin rpy = "${PI/2} -${PI/2} 0" xyz = "1 0.47 -0.575"/>
            <geometry>
                <mesh filename="package://bot_description/meshes/Link_5.STL" scale="0.01 0.01 0.01"/> 
            </geometry>            
        </collision>
    </link>

    <joint name = "joint_5" type = "revolute">
        <parent link = "link_4"/>
        <child link = "link_5"/>
        <axis xyz="0 1 0"/>
        <origin rpy = "0 0 0" xyz = "1.85 0 0"/>
        <limit lower="-2.268" upper="2.268" effort="${effort}" velocity="${velocity}"/>
    </joint>

    <link name = "link_6">
        <xacro:default_inertial mass="1.0"/>
        <visual>
            <origin rpy = "0 0 ${PI/2}" xyz = "0.07 -0.225 -8.895"/>
            <geometry>
                <mesh filename = "package://bot_description/meshes/Link_6.STL" scale = "0.01 0.01 0.01"/>
            </geometry>
        </visual>
        <collision>
            <origin rpy = "0 0 ${PI/2}" xyz = "0.07 -0.225 -8.895"/>
            <geometry>
                <mesh filename="package://bot_description/meshes/Link_6.STL" scale="0.01 0.01 0.01"/> 
            </geometry>            
        </collision>
    </link>

    <joint name = "joint_6" type = "revolute">
        <parent link = "link_5"/>
        <child link = "link_6"/>
        <axis xyz="1 0 0"/>
        <origin rpy = "0 0 0" xyz = "0.955 -0.05 0"/>
        <limit lower="-4.223" upper="4.223" effort="${effort}" velocity="${velocity}"/>
    </joint>

    <link name = "end_effector">
        <xacro:default_inertial mass="1.0"/>
        <visual>
            <origin rpy = "0 ${PI/2} 0" xyz = "-0.568 -0.219 0.219"/>
            <geometry>
                <mesh filename = "package://bot_description/meshes/End_effector.STL" scale = "0.01 0.01 0.01"/>
            </geometry>
        </visual>
        <collision>
            <origin rpy = "0 ${PI/2} 0" xyz = "-0.568 -0.219 0.219"/>
            <geometry>
                <mesh filename="package://bot_description/meshes/End_effector.STL" scale="0.01 0.01 0.01"/> 
            </geometry>            
        </collision>
    </link>

    <joint name = "joint_7" type = "fixed">
        <parent link = "link_6"/>
        <child link = "end_effector"/>
        <origin rpy = "0 0 0" xyz = "0.568 0 0"/>
    </joint>

    <xacro:default_transmission number = "1"/>
    <xacro:default_transmission number = "2"/>
    <xacro:default_transmission number = "3"/>
    <xacro:default_transmission number = "4"/>
    <xacro:default_transmission number = "5"/>
    <xacro:default_transmission number = "6"/>

</robot>